Workbook
Name z_95: Resumen!$C$5

Sheet Leeme
A1: Resultados de las corridas
A2: Qué es esta planilla | B2: Reúne los resultados numéricos de todas las simulaciones del trabajo «Evaluación mediante simulación del impacto de la Línea F sobre la operación de la red de Subte de Buenos Aires»: cada réplica tal como la dio el modelo y, a partir de ellas, las medias y los intervalos de confianza que cita el informe. Las medias, desvíos e intervalos están escritos como fórmulas que leen las hojas de réplicas, para que se pueda seguir la cuenta celda por celda.
A3: Los dos modelos de la red | B3: El modelo principal es el de AnyLogic: un pasajero por agente, toda la red durante un día hábil de 5 a 24 h. Además se escribió aparte, en Java y sin AnyLogic, un simulador de control con la misma lógica. Sirvió para verificar a AnyLogic (si dos programas hechos por separado dan lo mismo con los mismos datos, es muy improbable que compartan un error) y, como corre un día en menos de un segundo, para las variantes de frecuencia de la Línea F y de supuestos, que piden muchas corridas.
A4: Réplica | B4: Una simulación completa del día (o de la hora pico, en el submodelo de Constitución) con otra secuencia de números al azar. Cada réplica da un valor de cada medida; se hacen cien por escenario para separar el efecto real del azar.
A5: Intervalo de confianza del 95 % | B5: El margen (±) que acompaña a cada media. Se calcula como en Ross, Simulación, 2.ª ed., cap. 7: media ± z · S / √n, con z = 1,96, S el desvío entre réplicas y n la cantidad de réplicas (100). Con 95 % de confianza el valor verdadero está en ese rango. Si el intervalo de una diferencia entre escenarios no incluye el cero, la diferencia no es casual. En el submodelo de Constitución, con solo 10 réplicas, se usa en lugar de 1,96 el valor de la t de Student con n − 1 grados de libertad, que da un margen más ancho.
A6: Cómo se mide el efecto de la Línea F | B6: En el simulador de control los dos escenarios usan los mismos números al azar (la réplica i usa la semilla i en los dos), así que el efecto se calcula réplica a réplica: la diferencia de cada réplica y después su media e intervalo. En AnyLogic las réplicas de cada escenario usan números al azar distintos; el efecto es la diferencia de las medias y su margen combina los dos desvíos: 1,96 · √(S₁²/n + S₂²/n).
A7: Medidas | B7: Viaje medio: tiempo promedio de un viaje, desde que el pasajero entra a la red hasta que llega a destino (s). Espera media: tiempo promedio que un pasajero pasa en los andenes esperando el tren, sumando todas sus esperas (s). Ascensos por viaje: cuántos trenes toma en promedio cada pasajero (1 = sin transbordo). Pico de la Línea C (o de la F): pasajeros por hora a bordo en el tramo y la hora más cargados de la línea. Intervalo entre trenes: tiempo entre dos trenes seguidos de la misma línea y sentido.
A8: Hoja «Resumen» | B8: Media, desvío, n e intervalo de confianza de cada medida, por escenario: red actual y red con la Línea F con un tren cada 90, 100, 120, 150 y 189 s (simulador de control) y las dos corridas de AnyLogic. El escenario principal es la Línea F cada 100 s.
A9: Hoja «Efecto F100» | B9: El efecto de la Línea F cada 100 s sobre el viaje y la espera: diferencias réplica a réplica del simulador de control, y comparación con la diferencia de medias de AnyLogic.
A10: Hoja «Sensibilidad» | B10: El mismo efecto con cada supuesto propio del trabajo reemplazado por una alternativa (reparto horario de los viajes, capacidad de los trenes, pasajero que abandona, tiempo de detención). Si el efecto casi no cambia, la conclusión no depende de ese supuesto. Las réplicas están en «Sensibilidad réplicas».
A11: Hoja «Constitucion» | B11: Submodelo peatonal de la estación Constitución de la Línea F: diez réplicas de una hora pico por variante, con media, desvío e intervalo de confianza (t de Student), y las comparaciones entre variantes.
A12: Hojas «Control …» | B12: Las 100 réplicas del simulador de control de cada escenario: «Control base» es la red actual y «Control F90» a «Control F189», la red con la Línea F y el intervalo entre trenes indicado en segundos.
A13: Hojas «AnyLogic …» | B13: Las 100 réplicas del modelo de AnyLogic: red actual («AnyLogic sin F») y red con la Línea F cada 100 s («AnyLogic F100»). «AnyLogic frecuencias» tiene la red actual y la Línea F a cada intervalo entre trenes, diez réplicas por escenario, con su resumen.
A14: Celdas con fórmula | B14: El valor z = 1,96 está en una sola celda de la hoja «Resumen» con el nombre z_95; todas las fórmulas de intervalo lo usan. Las celdas de fondo amarillo son las cifras que cita el informe.

Sheet Resumen
A1: Resultados por escenario: media e intervalo de confianza del 95 %
A2: Método (Ross, Simulación, 2.ª ed., cap. 7): cada réplica da un valor de cada medida; se informa la media de las réplicas x̄ y su intervalo de confianza del 95 %, x̄ ± z_{α/2} · s / √n, con z = 1,96, s el desvío entre réplicas y n = 100 réplicas por escenario. «Desde» y «Hasta» son los extremos del intervalo. Las fórmulas leen las hojas de réplicas de cada escenario.
A3: Picos de carga: el simulador de control guarda, para cada tramo y hora, la media y el desvío de los pasajeros por hora entre las 100 réplicas; el pico es la celda (tramo, hora) de mayor media, así que su media, desvío y n se cargan como valores y solo el intervalo es fórmula. En AnyLogic el pico es el máximo de cada réplica (en cualquier tramo y hora), promediado después; por eso puede quedar algo por encima del del control. El cambio de la C respecto de la red actual es un cociente de dos medias; su margen se aproxima con la fórmula de primer orden: 1,96 · (b/a) · √((s_b/b)²/n_b + (s_a/a)²/n_a).
A5: Valor z del 95 % (z_{0,025}) | C5: 1.96
A7: Viaje medio (s)
A8: Modelo | B8: Escenario | C8: Media | D8: Desvío | E8: n | F8: IC 95 % (±) | G8: Desde | H8: Hasta
A9: Simulador de control | B9: Red actual (sin Línea F) | C9: =AVERAGE('Control base'!$E$2:$E$101) -> 1110.705 | D9: =_xlfn.STDEV.S('Control base'!$E$2:$E$101) -> 2.2181244 | E9: =COUNT('Control base'!$E$2:$E$101) -> 100 | F9: =z_95*D9/SQRT(E9) -> 0.43475238 | G9: =C9-F9 -> 1110.2702 | H9: =C9+F9 -> 1111.1398
A10: Simulador de control | B10: Con Línea F, un tren cada 90 s | C10: =AVERAGE('Control F90'!$E$2:$E$101) -> 1064.716 | D10: =_xlfn.STDEV.S('Control F90'!$E$2:$E$101) -> 1.9947264 | E10: =COUNT('Control F90'!$E$2:$E$101) -> 100 | F10: =z_95*D10/SQRT(E10) -> 0.39096637 | G10: =C10-F10 -> 1064.325 | H10: =C10+F10 -> 1065.107
A11: Simulador de control | B11: Con Línea F, un tren cada 100 s | C11: =AVERAGE('Control F100'!$E$2:$E$101) -> 1065.902 | D11: =_xlfn.STDEV.S('Control F100'!$E$2:$E$101) -> 2.2134566 | E11: =COUNT('Control F100'!$E$2:$E$101) -> 100 | F11: =z_95*D11/SQRT(E11) -> 0.43383748 | G11: =C11-F11 -> 1065.4682 | H11: =C11+F11 -> 1066.3358
A12: Simulador de control | B12: Con Línea F, un tren cada 120 s | C12: =AVERAGE('Control F120'!$E$2:$E$101) -> 1067.906 | D12: =_xlfn.STDEV.S('Control F120'!$E$2:$E$101) -> 2.1956256 | E12: =COUNT('Control F120'!$E$2:$E$101) -> 100 | F12: =z_95*D12/SQRT(E12) -> 0.43034262 | G12: =C12-F12 -> 1067.4757 | H12: =C12+F12 -> 1068.3363
A13: Simulador de control | B13: Con Línea F, un tren cada 150 s | C13: =AVERAGE('Control F150'!$E$2:$E$101) -> 1070.85 | D13: =_xlfn.STDEV.S('Control F150'!$E$2:$E$101) -> 2.4330427 | E13: =COUNT('Control F150'!$E$2:$E$101) -> 100 | F13: =z_95*D13/SQRT(E13) -> 0.47687638 | G13: =C13-F13 -> 1070.3731 | H13: =C13+F13 -> 1071.3269
A14: Simulador de control | B14: Con Línea F, un tren cada 189 s | C14: =AVERAGE('Control F189'!$E$2:$E$101) -> 1074.334 | D14: =_xlfn.STDEV.S('Control F189'!$E$2:$E$101) -> 2.0899094 | E14: =COUNT('Control F189'!$E$2:$E$101) -> 100 | F14: =z_95*D14/SQRT(E14) -> 0.40962224 | G14: =C14-F14 -> 1073.9244 | H14: =C14+F14 -> 1074.7436
A15: AnyLogic | B15: Red actual (sin Línea F) | C15: =AVERAGE('AnyLogic sin F'!$D$2:$D$101) -> 1110.792 | D15: =_xlfn.STDEV.S('AnyLogic sin F'!$D$2:$D$101) -> 2.2747041 | E15: =COUNT('AnyLogic sin F'!$D$2:$D$101) -> 100 | F15: =z_95*D15/SQRT(E15) -> 0.44584201 | G15: =C15-F15 -> 1110.3462 | H15: =C15+F15 -> 1111.2378
A16: AnyLogic | B16: Con Línea F, un tren cada 100 s | C16: =AVERAGE('AnyLogic F100'!$D$2:$D$101) -> 1065.409 | D16: =_xlfn.STDEV.S('AnyLogic F100'!$D$2:$D$101) -> 1.8858374 | E16: =COUNT('AnyLogic F100'!$D$2:$D$101) -> 100 | F16: =z_95*D16/SQRT(E16) -> 0.36962414 | G16: =C16-F16 -> 1065.0394 | H16: =C16+F16 -> 1065.7786
A18: Espera media (s)
A19: Modelo | B19: Escenario | C19: Media | D19: Desvío | E19: n | F19: IC 95 % (±) | G19: Desde | H19: Hasta
A20: Simulador de control | B20: Red actual (sin Línea F) | C20: =AVERAGE('Control base'!$F$2:$F$101) -> 188.503 | D20: =_xlfn.STDEV.S('Control base'!$F$2:$F$101) -> 2.1181016 | E20: =COUNT('Control base'!$F$2:$F$101) -> 100 | F20: =z_95*D20/SQRT(E20) -> 0.41514792 | G20: =C20-F20 -> 188.08785 | H20: =C20+F20 -> 188.91815
A21: Simulador de control | B21: Con Línea F, un tren cada 90 s | C21: =AVERAGE('Control F90'!$F$2:$F$101) -> 175.752 | D21: =_xlfn.STDEV.S('Control F90'!$F$2:$F$101) -> 2.0280597 | E21: =COUNT('Control F90'!$F$2:$F$101) -> 100 | F21: =z_95*D21/SQRT(E21) -> 0.39749971 | G21: =C21-F21 -> 175.3545 | H21: =C21+F21 -> 176.1495
A22: Simulador de control | B22: Con Línea F, un tren cada 100 s | C22: =AVERAGE('Control F100'!$F$2:$F$101) -> 176.885 | D22: =_xlfn.STDEV.S('Control F100'!$F$2:$F$101) -> 2.1435068 | E22: =COUNT('Control F100'!$F$2:$F$101) -> 100 | F22: =z_95*D22/SQRT(E22) -> 0.42012732 | G22: =C22-F22 -> 176.46487 | H22: =C22+F22 -> 177.30513
A23: Simulador de control | B23: Con Línea F, un tren cada 120 s | C23: =AVERAGE('Control F120'!$F$2:$F$101) -> 178.931 | D23: =_xlfn.STDEV.S('Control F120'!$F$2:$F$101) -> 2.2351957 | E23: =COUNT('Control F120'!$F$2:$F$101) -> 100 | F23: =z_95*D23/SQRT(E23) -> 0.43809837 | G23: =C23-F23 -> 178.4929 | H23: =C23+F23 -> 179.3691
A24: Simulador de control | B24: Con Línea F, un tren cada 150 s | C24: =AVERAGE('Control F150'!$F$2:$F$101) -> 181.864 | D24: =_xlfn.STDEV.S('Control F150'!$F$2:$F$101) -> 2.3781633 | E24: =COUNT('Control F150'!$F$2:$F$101) -> 100 | F24: =z_95*D24/SQRT(E24) -> 0.46612 | G24: =C24-F24 -> 181.39788 | H24: =C24+F24 -> 182.33012
A25: Simulador de control | B25: Con Línea F, un tren cada 189 s | C25: =AVERAGE('Control F189'!$F$2:$F$101) -> 185.309 | D25: =_xlfn.STDEV.S('Control F189'!$F$2:$F$101) -> 2.0701386 | E25: =COUNT('Control F189'!$F$2:$F$101) -> 100 | F25: =z_95*D25/SQRT(E25) -> 0.40574716 | G25: =C25-F25 -> 184.90325 | H25: =C25+F25 -> 185.71475
A26: AnyLogic | B26: Red actual (sin Línea F) | C26: =AVERAGE('AnyLogic sin F'!$E$2:$E$101) -> 188.501 | D26: =_xlfn.STDEV.S('AnyLogic sin F'!$E$2:$E$101) -> 2.2096435 | E26: =COUNT('AnyLogic sin F'!$E$2:$E$101) -> 100 | F26: =z_95*D26/SQRT(E26) -> 0.43309012 | G26: =C26-F26 -> 188.06791 | H26: =C26+F26 -> 188.93409
A27: AnyLogic | B27: Con Línea F, un tren cada 100 s | C27: =AVERAGE('AnyLogic F100'!$E$2:$E$101) -> 176.503 | D27: =_xlfn.STDEV.S('AnyLogic F100'!$E$2:$E$101) -> 1.8407539 | E27: =COUNT('AnyLogic F100'!$E$2:$E$101) -> 100 | F27: =z_95*D27/SQRT(E27) -> 0.36078776 | G27: =C27-F27 -> 176.14221 | H27: =C27+F27 -> 176.86379
A29: Ascensos por viaje
A30: Modelo | B30: Escenario | C30: Media | D30: Desvío | E30: n | F30: IC 95 % (±) | G30: Desde | H30: Hasta
A31: Simulador de control | B31: Red actual (sin Línea F) | C31: =AVERAGE('Control base'!$G$2:$G$101) -> 1.442707 | D31: =_xlfn.STDEV.S('Control base'!$G$2:$G$101) -> 0.00058331255 | E31: =COUNT('Control base'!$G$2:$G$101) -> 100 | F31: =z_95*D31/SQRT(E31) -> 0.00011432926 | G31: =C31-F31 -> 1.4425927 | H31: =C31+F31 -> 1.4428213
A32: Simulador de control | B32: Con Línea F, un tren cada 90 s | C32: =AVERAGE('Control F90'!$G$2:$G$101) -> 1.465676 | D32: =_xlfn.STDEV.S('Control F90'!$G$2:$G$101) -> 0.0006060503 | E32: =COUNT('Control F90'!$G$2:$G$101) -> 100 | F32: =z_95*D32/SQRT(E32) -> 0.00011878586 | G32: =C32-F32 -> 1.4655572 | H32: =C32+F32 -> 1.4657948
A33: Simulador de control | B33: Con Línea F, un tren cada 100 s | C33: =AVERAGE('Control F100'!$G$2:$G$101) -> 1.465741 | D33: =_xlfn.STDEV.S('Control F100'!$G$2:$G$101) -> 0.00064103688 | E33: =COUNT('Control F100'!$G$2:$G$101) -> 100 | F33: =z_95*D33/SQRT(E33) -> 0.00012564323 | G33: =C33-F33 -> 1.4656154 | H33: =C33+F33 -> 1.4658666
A34: Simulador de control | B34: Con Línea F, un tren cada 120 s | C34: =AVERAGE('Control F120'!$G$2:$G$101) -> 1.465699 | D34: =_xlfn.STDEV.S('Control F120'!$G$2:$G$101) -> 0.00060243529 | E34: =COUNT('Control F120'!$G$2:$G$101) -> 100 | F34: =z_95*D34/SQRT(E34) -> 0.00011807732 | G34: =C34-F34 -> 1.4655809 | H34: =C34+F34 -> 1.4658171
A35: Simulador de control | B35: Con Línea F, un tren cada 150 s | C35: =AVERAGE('Control F150'!$G$2:$G$101) -> 1.463846 | D35: =_xlfn.STDEV.S('Control F150'!$G$2:$G$101) -> 0.00057426633 | E35: =COUNT('Control F150'!$G$2:$G$101) -> 100 | F35: =z_95*D35/SQRT(E35) -> 0.0001125562 | G35: =C35-F35 -> 1.4637334 | H35: =C35+F35 -> 1.4639586
A36: Simulador de control | B36: Con Línea F, un tren cada 189 s | C36: =AVERAGE('Control F189'!$G$2:$G$101) -> 1.463136 | D36: =_xlfn.STDEV.S('Control F189'!$G$2:$G$101) -> 0.00069231277 | E36: =COUNT('Control F189'!$G$2:$G$101) -> 100 | F36: =z_95*D36/SQRT(E36) -> 0.0001356933 | G36: =C36-F36 -> 1.4630003 | H36: =C36+F36 -> 1.4632717
A37: AnyLogic | B37: Red actual (sin Línea F) | C37: =AVERAGE('AnyLogic sin F'!$F$2:$F$101) -> 1.442642 | D37: =_xlfn.STDEV.S('AnyLogic sin F'!$F$2:$F$101) -> 0.00061761679 | E37: =COUNT('AnyLogic sin F'!$F$2:$F$101) -> 100 | F37: =z_95*D37/SQRT(E37) -> 0.00012105289 | G37: =C37-F37 -> 1.4425209 | H37: =C37+F37 -> 1.4427631
A38: AnyLogic | B38: Con Línea F, un tren cada 100 s | C38: =AVERAGE('AnyLogic F100'!$F$2:$F$101) -> 1.465557 | D38: =_xlfn.STDEV.S('AnyLogic F100'!$F$2:$F$101) -> 0.0006564759 | E38: =COUNT('AnyLogic F100'!$F$2:$F$101) -> 100 | F38: =z_95*D38/SQRT(E38) -> 0.00012866928 | G38: =C38-F38 -> 1.4654283 | H38: =C38+F38 -> 1.4656857
A40: Pico de carga de la Línea C (pas./h)
A41: Modelo | B41: Escenario | C41: Media | D41: Desvío (pas./h) | E41: n | F41: IC 95 % (±) | G41: Desde | H41: Hasta | I41: Cambio respecto de la red actual (%) | J41: IC del cambio (± puntos %) | K41: Tramo y hora del pico
A42: Simulador de control | B42: Red actual (sin Línea F) | C42: 12435.8 | D42: 325.68 | E42: 100 | F42: =z_95*D42/SQRT(E42) -> 63.83328 | G42: =C42-F42 -> 12371.967 | H42: =C42+F42 -> 12499.633 | I42: — | K42: San Juan → Independencia, de 8 a 9 h
A43: Simulador de control | B43: Con Línea F, un tren cada 90 s | C43: 5624.87 | D43: 146.45 | E43: 100 | F43: =z_95*D43/SQRT(E43) -> 28.7042 | G43: =C43-F43 -> 5596.1658 | H43: =C43+F43 -> 5653.5742 | I43: =100*(C43/C$42-1) -> -54.768732 | J43: =100*z_95*(C43/C$42)*SQRT((D43/C43)^2/E43+(D$42/C$42)^2/E$42) -> 0.32738643 | K43: San Juan → Independencia, de 8 a 9 h
A44: Simulador de control | B44: Con Línea F, un tren cada 100 s | C44: 5639.3 | D44: 186.52 | E44: 100 | F44: =z_95*D44/SQRT(E44) -> 36.55792 | G44: =C44-F44 -> 5602.7421 | H44: =C44+F44 -> 5675.8579 | I44: =100*(C44/C$42-1) -> -54.652696 | J44: =100*z_95*(C44/C$42)*SQRT((D44/C44)^2/E44+(D$42/C$42)^2/E$42) -> 0.37496879 | K44: San Juan → Independencia, de 8 a 9 h
A45: Simulador de control | B45: Con Línea F, un tren cada 120 s | C45: 5661.91 | D45: 140.89 | E45: 100 | F45: =z_95*D45/SQRT(E45) -> 27.61444 | G45: =C45-F45 -> 5634.2956 | H45: =C45+F45 -> 5689.5244 | I45: =100*(C45/C$42-1) -> -54.470882 | J45: =100*z_95*(C45/C$42)*SQRT((D45/C45)^2/E45+(D$42/C$42)^2/E$42) -> 0.32237486 | K45: San Juan → Independencia, de 8 a 9 h
...

Sheet Efecto F100
A1: Réplica | B1: Viaje sin F (s) | C1: Viaje con F (s) | D1: Diferencia de viaje (s) | E1: Espera sin F (s) | F1: Espera con F (s) | G1: Diferencia de espera (s) | I1: Efecto de la Línea F cada 100 s (con F − sin F); negativo = baja
A2: ='Control base'!A2 -> 1 | B2: ='Control base'!E2 -> 1108.8 | C2: ='Control F100'!E2 -> 1068.1 | D2: =C2-B2 -> -40.7 | E2: ='Control base'!F2 -> 186.9 | F2: ='Control F100'!F2 -> 178.5 | G2: =F2-E2 -> -8.4
A3: ='Control base'!A3 -> 2 | B3: ='Control base'!E3 -> 1110.3 | C3: ='Control F100'!E3 -> 1065.4 | D3: =C3-B3 -> -44.9 | E3: ='Control base'!F3 -> 188.1 | F3: ='Control F100'!F3 -> 175.9 | G3: =F3-E3 -> -12.2 | I3: Simulador de control: diferencia réplica a réplica (mismos números al azar en los dos escenarios)
A4: ='Control base'!A4 -> 3 | B4: ='Control base'!E4 -> 1109.9 | C4: ='Control F100'!E4 -> 1064.6 | D4: =C4-B4 -> -45.3 | E4: ='Control base'!F4 -> 187.6 | F4: ='Control F100'!F4 -> 175.5 | G4: =F4-E4 -> -12.1 | I4: Medida | J4: Media de la diferencia | K4: Desvío | L4: n | M4: IC 95 % (±) | N4: Desde | O4: Hasta
A5: ='Control base'!A5 -> 4 | B5: ='Control base'!E5 -> 1107.2 | C5: ='Control F100'!E5 -> 1064.1 | D5: =C5-B5 -> -43.1 | E5: ='Control base'!F5 -> 184.9 | F5: ='Control F100'!F5 -> 174.6 | G5: =F5-E5 -> -10.3 | I5: Viaje medio (s) | J5: =AVERAGE($D$2:$D$101) -> -44.803 | K5: =_xlfn.STDEV.S($D$2:$D$101) -> 2.9571504 | L5: =COUNT($D$2:$D$101) -> 100 | M5: =z_95*K5/SQRT(L5) -> 0.57960147 | N5: =J5-M5 -> -45.382601 | O5: =J5+M5 -> -44.223399
A6: ='Control base'!A6 -> 5 | B6: ='Control base'!E6 -> 1111 | C6: ='Control F100'!E6 -> 1066 | D6: =C6-B6 -> -45 | E6: ='Control base'!F6 -> 188.8 | F6: ='Control F100'!F6 -> 177.5 | G6: =F6-E6 -> -11.3 | I6: Espera media (s) | J6: =AVERAGE($G$2:$G$101) -> -11.618 | K6: =_xlfn.STDEV.S($G$2:$G$101) -> 2.8397034 | L6: =COUNT($G$2:$G$101) -> 100 | M6: =z_95*K6/SQRT(L6) -> 0.55658186 | N6: =J6-M6 -> -12.174582 | O6: =J6+M6 -> -11.061418
A7: ='Control base'!A7 -> 6 | B7: ='Control base'!E7 -> 1110.5 | C7: ='Control F100'!E7 -> 1069.3 | D7: =C7-B7 -> -41.2 | E7: ='Control base'!F7 -> 187.2 | F7: ='Control F100'!F7 -> 180.6 | G7: =F7-E7 -> -6.6 | I7: Pico de la Línea C (cambio %) | J7: =Resumen!I44 -> -54.652696 | M7: =Resumen!J44 -> 0.37496879 | N7: =J7-M7 -> -55.027665 | O7: =J7+M7 -> -54.277727
A8: ='Control base'!A8 -> 7 | B8: ='Control base'!E8 -> 1110.2 | C8: ='Control F100'!E8 -> 1067.2 | D8: =C8-B8 -> -43 | E8: ='Control base'!F8 -> 188.2 | F8: ='Control F100'!F8 -> 177.6 | G8: =F8-E8 -> -10.6 | I8: El pico de la C no tiene un valor por réplica en el simulador de control (se guarda la media y el desvío de cada tramo y hora); su cambio se calcula en «Resumen» como cociente de dos medias.
A9: ='Control base'!A9 -> 8 | B9: ='Control base'!E9 -> 1110.7 | C9: ='Control F100'!E9 -> 1062.5 | D9: =C9-B9 -> -48.2 | E9: ='Control base'!F9 -> 189.1 | F9: ='Control F100'!F9 -> 174.5 | G9: =F9-E9 -> -14.6
A10: ='Control base'!A10 -> 9 | B10: ='Control base'!E10 -> 1110.6 | C10: ='Control F100'!E10 -> 1064.4 | D10: =C10-B10 -> -46.2 | E10: ='Control base'!F10 -> 188.4 | F10: ='Control F100'!F10 -> 175.7 | G10: =F10-E10 -> -12.7
A11: ='Control base'!A11 -> 10 | B11: ='Control base'!E11 -> 1111 | C11: ='Control F100'!E11 -> 1064.9 | D11: =C11-B11 -> -46.1 | E11: ='Control base'!F11 -> 189.1 | F11: ='Control F100'!F11 -> 176.1 | G11: =F11-E11 -> -13 | I11: AnyLogic: diferencia de medias (réplicas con números al azar distintos en cada escenario)
A12: ='Control base'!A12 -> 11 | B12: ='Control base'!E12 -> 1110.4 | C12: ='Control F100'!E12 -> 1068.3 | D12: =C12-B12 -> -42.1 | E12: ='Control base'!F12 -> 188.8 | F12: ='Control F100'!F12 -> 180 | G12: =F12-E12 -> -8.8 | I12: Medida | J12: Media sin F | K12: Media con F | L12: Desvío sin F | M12: Desvío con F | N12: n sin F | O12: n con F | P12: Diferencia | Q12: IC 95 % (±) | R12: Desde | S12: Hasta
A13: ='Control base'!A13 -> 12 | B13: ='Control base'!E13 -> 1110 | C13: ='Control F100'!E13 -> 1067.1 | D13: =C13-B13 -> -42.9 | E13: ='Control base'!F13 -> 187.8 | F13: ='Control F100'!F13 -> 177.4 | G13: =F13-E13 -> -10.4 | I13: Viaje medio (s) | J13: =AVERAGE('AnyLogic sin F'!$D$2:$D$101) -> 1110.792 | K13: =AVERAGE('AnyLogic F100'!$D$2:$D$101) -> 1065.409 | L13: =_xlfn.STDEV.S('AnyLogic sin F'!$D$2:$D$101) -> 2.2747041 | M13: =_xlfn.STDEV.S('AnyLogic F100'!$D$2:$D$101) -> 1.8858374 | N13: =COUNT('AnyLogic sin F'!$D$2:$D$101) -> 100 | O13: =COUNT('AnyLogic F100'!$D$2:$D$101) -> 100 | P13: =K13-J13 -> -45.383 | Q13: =z_95*SQRT(L13^2/N13+M13^2/O13) -> 0.57913478 | R13: =P13-Q13 -> -45.962135 | S13: =P13+Q13 -> -44.803865
A14: ='Control base'!A14 -> 13 | B14: ='Control base'!E14 -> 1111.4 | C14: ='Control F100'!E14 -> 1063.5 | D14: =C14-B14 -> -47.9 | E14: ='Control base'!F14 -> 188.2 | F14: ='Control F100'!F14 -> 174.7 | G14: =F14-E14 -> -13.5 | I14: Espera media (s) | J14: =AVERAGE('AnyLogic sin F'!$E$2:$E$101) -> 188.501 | K14: =AVERAGE('AnyLogic F100'!$E$2:$E$101) -> 176.503 | L14: =_xlfn.STDEV.S('AnyLogic sin F'!$E$2:$E$101) -> 2.2096435 | M14: =_xlfn.STDEV.S('AnyLogic F100'!$E$2:$E$101) -> 1.8407539 | N14: =COUNT('AnyLogic sin F'!$E$2:$E$101) -> 100 | O14: =COUNT('AnyLogic F100'!$E$2:$E$101) -> 100 | P14: =K14-J14 -> -11.998 | Q14: =z_95*SQRT(L14^2/N14+M14^2/O14) -> 0.56367975 | R14: =P14-Q14 -> -12.56168 | S14: =P14+Q14 -> -11.43432
A15: ='Control base'!A15 -> 14 | B15: ='Control base'!E15 -> 1109.8 | C15: ='Control F100'!E15 -> 1063.9 | D15: =C15-B15 -> -45.9 | E15: ='Control base'!F15 -> 188.2 | F15: ='Control F100'!F15 -> 174.9 | G15: =F15-E15 -> -13.3 | I15: Ascensos por viaje | J15: =AVERAGE('AnyLogic sin F'!$F$2:$F$101) -> 1.442642 | K15: =AVERAGE('AnyLogic F100'!$F$2:$F$101) -> 1.465557 | L15: =_xlfn.STDEV.S('AnyLogic sin F'!$F$2:$F$101) -> 0.00061761679 | M15: =_xlfn.STDEV.S('AnyLogic F100'!$F$2:$F$101) -> 0.0006564759 | N15: =COUNT('AnyLogic sin F'!$F$2:$F$101) -> 100 | O15: =COUNT('AnyLogic F100'!$F$2:$F$101) -> 100 | P15: =K15-J15 -> 0.022915 | Q15: =z_95*SQRT(L15^2/N15+M15^2/O15) -> 0.00017666235 | R15: =P15-Q15 -> 0.022738338 | S15: =P15+Q15 -> 0.023091662
A16: ='Control base'!A16 -> 15 | B16: ='Control base'!E16 -> 1112.1 | C16: ='Control F100'!E16 -> 1065 | D16: =C16-B16 -> -47.1 | E16: ='Control base'!F16 -> 189.6 | F16: ='Control F100'!F16 -> 176 | G16: =F16-E16 -> -13.6 | I16: Pico de la Línea C (pas./h) | J16: =IF(COUNT('AnyLogic sin F'!$S$2:$S$101)<2,"",AVERAGE('AnyLogic sin F'!$S$2:$S$101)) -> 12463.45 | K16: =IF(COUNT('AnyLogic F100'!$T$2:$T$101)<2,"",AVERAGE('AnyLogic F100'!$T$2:$T$101)) -> 5693.8 | L16: =IF(COUNT('AnyLogic sin F'!$S$2:$S$101)<2,"",_xlfn.STDEV.S('AnyLogic sin F'!$S$2:$S$101)) -> 281.48895 | M16: =IF(COUNT('AnyLogic F100'!$T$2:$T$101)<2,"",_xlfn.STDEV.S('AnyLogic F100'!$T$2:$T$101)) -> 138.25924 | N16: =IF(COUNT('AnyLogic sin F'!$S$2:$S$101)<2,"",COUNT('AnyLogic sin F'!$S$2:$S$101)) -> 100 | O16: =IF(COUNT('AnyLogic F100'!$T$2:$T$101)<2,"",COUNT('AnyLogic F100'!$T$2:$T$101)) -> 100 | P16: =IF(OR(J16="",K16=""),"",K16-J16) -> -6769.65 | Q16: =IF(OR(J16="",K16=""),"",z_95*SQRT(L16^2/N16+M16^2/O16)) -> 61.467689 | R16: =IF(OR(J16="",K16=""),"",P16-Q16) -> -6831.1177 | S16: =IF(OR(J16="",K16=""),"",P16+Q16) -> -6708.1823
A17: ='Control base'!A17 -> 16 | B17: ='Control base'!E17 -> 1107.8 | C17: ='Control F100'!E17 -> 1067.4 | D17: =C17-B17 -> -40.4 | E17: ='Control base'!F17 -> 186.1 | F17: ='Control F100'!F17 -> 178.5 | G17: =F17-E17 -> -7.6 | I17: Pico de la Línea C (cambio %) | P17: =IF(OR(J16="",K16=""),"",100*(K16/J16-1)) -> -54.31602 | Q17: =IF(OR(J16="",K16=""),"",100*z_95*(K16/J16)*SQRT((M16/K16)^2/O16+(L16/J16)^2/N16)) -> 0.29693546 | R17: =IF(P17="","",P17-Q17) -> -54.612956 | S17: =IF(P17="","",P17+Q17) -> -54.019085
A18: ='Control base'!A18 -> 17 | B18: ='Control base'!E18 -> 1109.8 | C18: ='Control F100'!E18 -> 1062.7 | D18: =C18-B18 -> -47.1 | E18: ='Control base'!F18 -> 187.3 | F18: ='Control F100'!F18 -> 174.2 | G18: =F18-E18 -> -13.1 | I18: IC de la diferencia en AnyLogic: 1,96 · √(S₁²/n₁ + S₂²/n₂). El pico de la C de AnyLogic es el máximo de cada réplica, promediado; queda vacío si las réplicas no lo traen.
A19: ='Control base'!A19 -> 18 | B19: ='Control base'!E19 -> 1114.2 | C19: ='Control F100'!E19 -> 1067.9 | D19: =C19-B19 -> -46.3 | E19: ='Control base'!F19 -> 192.6 | F19: ='Control F100'!F19 -> 178.7 | G19: =F19-E19 -> -13.9
A20: ='Control base'!A20 -> 19 | B20: ='Control base'!E20 -> 1110.1 | C20: ='Control F100'!E20 -> 1065.3 | D20: =C20-B20 -> -44.8 | E20: ='Control base'!F20 -> 187.7 | F20: ='Control F100'!F20 -> 176.6 | G20: =F20-E20 -> -11.1
A21: ='Control base'!A21 -> 20 | B21: ='Control base'!E21 -> 1112.7 | C21: ='Control F100'!E21 -> 1066.1 | D21: =C21-B21 -> -46.6 | E21: ='Control base'!F21 -> 190.1 | F21: ='Control F100'!F21 -> 176.6 | G21: =F21-E21 -> -13.5
A22: ='Control base'!A22 -> 21 | B22: ='Control base'!E22 -> 1110.9 | C22: ='Control F100'!E22 -> 1064.6 | D22: =C22-B22 -> -46.3 | E22: ='Control base'!F22 -> 187.8 | F22: ='Control F100'!F22 -> 175 | G22: =F22-E22 -> -12.8
A23: ='Control base'!A23 -> 22 | B23: ='Control base'!E23 -> 1110.8 | C23: ='Control F100'!E23 -> 1063.4 | D23: =C23-B23 -> -47.4 | E23: ='Control base'!F23 -> 188.2 | F23: ='Control F100'!F23 -> 174 | G23: =F23-E23 -> -14.2
A24: ='Control base'!A24 -> 23 | B24: ='Control base'!E24 -> 1109.3 | C24: ='Control F100'!E24 -> 1067.3 | D24: =C24-B24 -> -42 | E24: ='Control base'!F24 -> 187 | F24: ='Control F100'!F24 -> 178.6 | G24: =F24-E24 -> -8.4
A25: ='Control base'!A25 -> 24 | B25: ='Control base'!E25 -> 1108.5 | C25: ='Control F100'!E25 -> 1070 | D25: =C25-B25 -> -38.5 | E25: ='Control base'!F25 -> 186.4 | F25: ='Control F100'!F25 -> 180.8 | G25: =F25-E25 -> -5.6
A26: ='Control base'!A26 -> 25 | B26: ='Control base'!E26 -> 1108.4 | C26: ='Control F100'!E26 -> 1062.6 | D26: =C26-B26 -> -45.8 | E26: ='Control base'!F26 -> 186.3 | F26: ='Control F100'!F26 -> 173.6 | G26: =F26-E26 -> -12.7
A27: ='Control base'!A27 -> 26 | B27: ='Control base'!E27 -> 1112 | C27: ='Control F100'!E27 -> 1066.9 | D27: =C27-B27 -> -45.1 | E27: ='Control base'!F27 -> 189.3 | F27: ='Control F100'!F27 -> 177.8 | G27: =F27-E27 -> -11.5
A28: ='Control base'!A28 -> 27 | B28: ='Control base'!E28 -> 1108.9 | C28: ='Control F100'!E28 -> 1063.9 | D28: =C28-B28 -> -45 | E28: ='Control base'!F28 -> 187.3 | F28: ='Control F100'!F28 -> 174.8 | G28: =F28-E28 -> -12.5
A29: ='Control base'!A29 -> 28 | B29: ='Control base'!E29 -> 1106.3 | C29: ='Control F100'!E29 -> 1065.7 | D29: =C29-B29 -> -40.6 | E29: ='Control base'!F29 -> 183.8 | F29: ='Control F100'!F29 -> 176.5 | G29: =F29-E29 -> -7.3
A30: ='Control base'!A30 -> 29 | B30: ='Control base'!E30 -> 1112 | C30: ='Control F100'!E30 -> 1064.1 | D30: =C30-B30 -> -47.9 | E30: ='Control base'!F30 -> 190.4 | F30: ='Control F100'!F30 -> 175.6 | G30: =F30-E30 -> -14.8
... A101: ='Control base'!A101 -> 100 | B101: ='Control base'!E101 -> 1110 | C101: ='Control F100'!E101 -> 1066.1 | D101: =C101-B101 -> -43.9 | E101: ='Control base'!F101 -> 187.7 | F101: ='Control F100'!F101 -> 178.1 | G101: =F101-E101 -> -9.6

Sheet Sensibilidad
A1: Efecto de la Línea F (un tren cada 100 s) con cada supuesto reemplazado por una alternativa
A2: Cada fila repite la comparación entre la red actual y la red con la Línea F cada 100 s cambiando un solo supuesto (simulador de control, 100 réplicas por escenario, mismos números al azar en los dos). El efecto en el viaje y en la espera es la media de las diferencias réplica a réplica ± 1,96 · s / √n. El pico de la C es la celda tramo-hora de mayor carga media; su cambio es un cociente de dos medias con margen de primer orden. Si el efecto casi no cambia entre filas, la conclusión no depende de ese supuesto.
A4: Variante | B4: Qué cambia | C4: Efecto en el viaje (s) | D4: Desvío | E4: n | F4: IC 95 % (±) | G4: Efecto en la espera (s) | H4: Desvío | I4: n | J4: IC 95 % (±) | K4: Pico C sin F (pas./h) | L4: Desvío | M4: Pico C con F (pas./h) | N4: Desvío | O4: Cambio en el pico de la C (%) | P4: IC del cambio (± puntos %)
A5: Supuestos del trabajo | B5: Perfil horario propio de cada par origen–destino; quien no entra al tren espera el siguiente; la detención depende de los pasajeros que suben y bajan. | C5: =AVERAGE('Efecto F100'!$D$2:$D$101) -> -44.803 | D5: =_xlfn.STDEV.S('Efecto F100'!$D$2:$D$101) -> 2.9571504 | E5: =COUNT('Efecto F100'!$D$2:$D$101) -> 100 | F5: =z_95*D5/SQRT(E5) -> 0.57960147 | G5: =AVERAGE('Efecto F100'!$G$2:$G$101) -> -11.618 | H5: =_xlfn.STDEV.S('Efecto F100'!$G$2:$G$101) -> 2.8397034 | I5: =COUNT('Efecto F100'!$G$2:$G$101) -> 100 | J5: =z_95*H5/SQRT(I5) -> 0.55658186 | K5: 12435.8 | L5: 325.68 | M5: 5639.3 | N5: 186.52 | O5: =100*(M5/K5-1) -> -54.652696 | P5: =100*z_95*(M5/K5)*SQRT((N5/M5)^2/I5+(L5/K5)^2/I5) -> 0.37496879
A6: Una sola curva horaria para la red | B6: Fuera de las dos horas pico, los viajes de todos los pares origen–destino se reparten en el día con una misma curva, la del conjunto de la red, en vez del perfil propio de cada par. | C6: =AVERAGE('Sensibilidad réplicas'!$D$2:$D$101) -> -45.311 | D6: =_xlfn.STDEV.S('Sensibilidad réplicas'!$D$2:$D$101) -> 2.7133748 | E6: =COUNT('Sensibilidad réplicas'!$D$2:$D$101) -> 100 | F6: =z_95*D6/SQRT(E6) -> 0.53182147 | G6: =AVERAGE('Sensibilidad réplicas'!$G$2:$G$101) -> -11.965 | H6: =_xlfn.STDEV.S('Sensibilidad réplicas'!$G$2:$G$101) -> 2.6073468 | I6: =COUNT('Sensibilidad réplicas'!$G$2:$G$101) -> 100 | J6: =z_95*H6/SQRT(I6) -> 0.51103998 | K6: 11986.98 | L6: 271.2 | M6: 5483.2 | N6: 129.7 | O6: =100*(M6/K6-1) -> -54.257036 | P6: =100*z_95*(M6/K6)*SQRT((N6/M6)^2/I6+(L6/K6)^2/I6) -> 0.2934629
A7: Viajes parejos fuera de las horas pico | B7: Fuera de las dos horas pico, los viajes de cada par se reparten en partes iguales entre las horas (caso extremo, poco realista). | C7: =AVERAGE('Sensibilidad réplicas'!$J$2:$J$101) -> -47.776 | D7: =_xlfn.STDEV.S('Sensibilidad réplicas'!$J$2:$J$101) -> 2.9615079 | E7: =COUNT('Sensibilidad réplicas'!$J$2:$J$101) -> 100 | F7: =z_95*D7/SQRT(E7) -> 0.58045556 | G7: =AVERAGE('Sensibilidad réplicas'!$M$2:$M$101) -> -14.233 | H7: =_xlfn.STDEV.S('Sensibilidad réplicas'!$M$2:$M$101) -> 2.8549463 | I7: =COUNT('Sensibilidad réplicas'!$M$2:$M$101) -> 100 | J7: =z_95*H7/SQRT(I7) -> 0.55956947 | K7: 11861.86 | L7: 233.28 | M7: 5446.83 | N7: 126.14 | O7: =100*(M7/K7-1) -> -54.081147 | P7: =100*z_95*(M7/K7)*SQRT((N7/M7)^2/I7+(L7/K7)^2/I7) -> 0.27344292
A8: Trenes sin límite de capacidad | B8: Todos los que esperan suben al tren que llega; nadie queda en el andén por tren lleno. | C8: =AVERAGE('Sensibilidad réplicas'!$P$2:$P$101) -> -44.826 | D8: =_xlfn.STDEV.S('Sensibilidad réplicas'!$P$2:$P$101) -> 2.4393086 | E8: =COUNT('Sensibilidad réplicas'!$P$2:$P$101) -> 100 | F8: =z_95*D8/SQRT(E8) -> 0.47810448 | G8: =AVERAGE('Sensibilidad réplicas'!$S$2:$S$101) -> -11.619 | H8: =_xlfn.STDEV.S('Sensibilidad réplicas'!$S$2:$S$101) -> 2.2722167 | I8: =COUNT('Sensibilidad réplicas'!$S$2:$S$101) -> 100 | J8: =z_95*H8/SQRT(I8) -> 0.44535447 | K8: 12405.2 | L8: 310.51 | M8: 5639.3 | N8: 186.52 | O8: =100*(M8/K8-1) -> -54.540838 | P8: =100*z_95*(M8/K8)*SQRT((N8/M8)^2/I8+(L8/K8)^2/I8) -> 0.36957584
A9: El pasajero se va tras perder dos trenes | B9: Quien ve partir dos trenes llenos abandona el viaje (en la base, espera hasta poder subir). | C9: =AVERAGE('Sensibilidad réplicas'!$V$2:$V$101) -> -44.869 | D9: =_xlfn.STDEV.S('Sensibilidad réplicas'!$V$2:$V$101) -> 2.5952441 | E9: =COUNT('Sensibilidad réplicas'!$V$2:$V$101) -> 100 | F9: =z_95*D9/SQRT(E9) -> 0.50866784 | G9: =AVERAGE('Sensibilidad réplicas'!$Y$2:$Y$101) -> -11.686 | H9: =_xlfn.STDEV.S('Sensibilidad réplicas'!$Y$2:$Y$101) -> 2.4376268 | I9: =COUNT('Sensibilidad réplicas'!$Y$2:$Y$101) -> 100 | J9: =z_95*H9/SQRT(I9) -> 0.47777485 | K9: 12422.61 | L9: 321.67 | M9: 5639.3 | N9: 186.52 | O9: =100*(M9/K9-1) -> -54.604548 | P9: =100*z_95*(M9/K9)*SQRT((N9/M9)^2/I9+(L9/K9)^2/I9) -> 0.37374326
A10: Detención fija en estación | B10: El tren se detiene siempre el mínimo de diseño (24 s; 30 s en la Línea F), sin sumar tiempo por pasajero que sube o baja. | C10: =AVERAGE('Sensibilidad réplicas'!$AB$2:$AB$101) -> -44.792 | D10: =_xlfn.STDEV.S('Sensibilidad réplicas'!$AB$2:$AB$101) -> 2.9437721 | E10: =COUNT('Sensibilidad réplicas'!$AB$2:$AB$101) -> 100 | F10: =z_95*D10/SQRT(E10) -> 0.57697932 | G10: =AVERAGE('Sensibilidad réplicas'!$AE$2:$AE$101) -> -11.605 | H10: =_xlfn.STDEV.S('Sensibilidad réplicas'!$AE$2:$AE$101) -> 2.8358233 | I10: =COUNT('Sensibilidad réplicas'!$AE$2:$AE$101) -> 100 | J10: =z_95*H10/SQRT(I10) -> 0.55582137 | K10: 12435.8 | L10: 325.68 | M10: 5639.3 | N10: 186.52 | O10: =100*(M10/K10-1) -> -54.652696 | P10: =100*z_95*(M10/K10)*SQRT((N10/M10)^2/I10+(L10/K10)^2/I10) -> 0.37496879
A11: Doble tiempo de detención por pasajero | B11: Se duplica el tiempo que agrega cada pasajero que baja (1,85 s) o sube (2,1 s). | C11: =AVERAGE('Sensibilidad réplicas'!$AH$2:$AH$101) -> -45.558 | D11: =_xlfn.STDEV.S('Sensibilidad réplicas'!$AH$2:$AH$101) -> 3.1260127 | E11: =COUNT('Sensibilidad réplicas'!$AH$2:$AH$101) -> 100 | F11: =z_95*D11/SQRT(E11) -> 0.61269849 | G11: =AVERAGE('Sensibilidad réplicas'!$AK$2:$AK$101) -> -11.913 | H11: =_xlfn.STDEV.S('Sensibilidad réplicas'!$AK$2:$AK$101) -> 2.9116157 | I11: =COUNT('Sensibilidad réplicas'!$AK$2:$AK$101) -> 100 | J11: =z_95*H11/SQRT(I11) -> 0.57067668 | K11: 12435.8 | L11: 325.68 | M11: 5639.3 | N11: 186.52 | O11: =100*(M11/K11-1) -> -54.652696 | P11: =100*z_95*(M11/K11)*SQRT((N11/M11)^2/I11+(L11/K11)^2/I11) -> 0.37496879
A12: Triple tiempo de detención por pasajero | B12: Se triplica el tiempo que agrega cada pasajero que baja o sube. | C12: =AVERAGE('Sensibilidad réplicas'!$AN$2:$AN$101) -> -46.925 | D12: =_xlfn.STDEV.S('Sensibilidad réplicas'!$AN$2:$AN$101) -> 3.4980622 | E12: =COUNT('Sensibilidad réplicas'!$AN$2:$AN$101) -> 100 | F12: =z_95*D12/SQRT(E12) -> 0.6856202 | G12: =AVERAGE('Sensibilidad réplicas'!$AQ$2:$AQ$101) -> -12.4 | H12: =_xlfn.STDEV.S('Sensibilidad réplicas'!$AQ$2:$AQ$101) -> 3.0496895 | I12: =COUNT('Sensibilidad réplicas'!$AQ$2:$AQ$101) -> 100 | J12: =z_95*H12/SQRT(I12) -> 0.59773914 | K12: 12435.8 | L12: 325.68 | M12: 5639.3 | N12: 186.52 | O12: =100*(M12/K12-1) -> -54.652696 | P12: =100*z_95*(M12/K12)*SQRT((N12/M12)^2/I12+(L12/K12)^2/I12) -> 0.37496879
A14: La n del pico (100 réplicas) se toma de la columna n de la espera, que cuenta las mismas réplicas.

Sheet Constitucion
A1: Submodelo peatonal de la estación Constitución de la Línea F (una hora pico por réplica)
A2: Diez réplicas por variante: menos que las cien de la red, porque cada una mueve miles de peatones por cuatro niveles y tarda varios minutos. Por eso el intervalo usa la t de Student con n − 1 grados de libertad en lugar de 1,96: IC = t · s / √n, con t = INV.T.2C(0,05; n − 1) (2,262 para n = 10), que da un margen más ancho. Las comparaciones entre variantes son diferencias de medias con muestras independientes; su margen es t · √(s₁²/n₁ + s₂²/n₂) con los grados de libertad de Welch.
A3: La variante de la tarde con las mecánicas del lado Roca en el sentido de la hora pico tiene solo tres réplicas: el modelo se detuvo por un error de la biblioteca peatonal en la tercera, a los 55 minutos simulados, y esa réplica casi completa se conserva.
A5: Comparaciones entre variantes (variante − caso base)
A6: Comparación | B6: Medida | C6: Base: media | D6: Base: desvío | E6: Base: n | F6: Variante: media | G6: Variante: desvío | H6: Variante: n | I6: Diferencia (s) | J6: Grados de libertad (Welch) | K6: t de Student | L6: IC 95 % (±) | M6: Desde | N6: Hasta | O6: Cambio (%)
A7: Si solo el 30 % fuera del Roca (mañana) | B7: Entrada → tren, media (s) | C7: =F31 -> 167.36 | D7: =F32 -> 0.4812022 | E7: =F33 -> 10 | F7: =F49 -> 164.01 | G7: =F50 -> 0.44833024 | H7: =F51 -> 10 | I7: =F7-C7 -> -3.35 | J7: =(D7^2/E7+G7^2/H7)^2/((D7^2/E7)^2/(E7-1)+(G7^2/H7)^2/(H7-1)) -> 17.910627 | K7: =_xlfn.T.INV.2T(0.05,J7) -> 2.1098156 | L7: =K7*SQRT(D7^2/E7+G7^2/H7) -> 0.43879881 | M7: =I7-L7 -> -3.7887988 | N7: =I7+L7 -> -2.9112012 | O7: =100*I7/C7 -> -2.001673
A8: Si solo el 30 % fuera del Roca (mañana) | B8: Tren → salida, media (s) | C8: =K31 -> 162.59 | D8: =K32 -> 1.2661841 | E8: =K33 -> 10 | F8: =K49 -> 158.8 | G8: =K50 -> 1.1556624 | H8: =K51 -> 10 | I8: =F8-C8 -> -3.79 | J8: =(D8^2/E8+G8^2/H8)^2/((D8^2/E8)^2/(E8-1)+(G8^2/H8)^2/(H8-1)) -> 17.851905 | K8: =_xlfn.T.INV.2T(0.05,J8) -> 2.1098156 | L8: =K8*SQRT(D8^2/E8+G8^2/H8) -> 1.1437415 | M8: =I8-L8 -> -4.9337415 | N8: =I8+L8 -> -2.6462585 | O8: =100*I8/C8 -> -2.3310167
A9: Si solo el 30 % fuera del Roca (tarde) | B9: Entrada → tren, media (s) | C9: =F85 -> 158.67 | D9: =F86 -> 0.56969778 | E9: =F87 -> 10 | F9: =F103 -> 155.21 | G9: =F104 -> 0.91098238 | H9: =F105 -> 10 | I9: =F9-C9 -> -3.46 | J9: =(D9^2/E9+G9^2/H9)^2/((D9^2/E9)^2/(E9-1)+(G9^2/H9)^2/(H9-1)) -> 15.10566 | K9: =_xlfn.T.INV.2T(0.05,J9) -> 2.1314495 | L9: =K9*SQRT(D9^2/E9+G9^2/H9) -> 0.72420509 | M9: =I9-L9 -> -4.1842051 | N9: =I9+L9 -> -2.7357949 | O9: =100*I9/C9 -> -2.1806265
A10: Si solo el 30 % fuera del Roca (tarde) | B10: Tren → salida, media (s) | C10: =K85 -> 163.69 | D10: =K86 -> 0.4794673 | E10: =K87 -> 10 | F10: =K103 -> 159.72 | G10: =K104 -> 0.6214678 | H10: =K105 -> 10 | I10: =F10-C10 -> -3.97 | J10: =(D10^2/E10+G10^2/H10)^2/((D10^2/E10)^2/(E10-1)+(G10^2/H10)^2/(H10-1)) -> 16.911173 | K10: =_xlfn.T.INV.2T(0.05,J10) -> 2.1199053 | L10: =K10*SQRT(D10^2/E10+G10^2/H10) -> 0.52619411 | M10: =I10-L10 -> -4.4961941 | N10: =I10+L10 -> -3.4438059 | O10: =100*I10/C10 -> -2.4253161
A11: Mecánicas del lado Roca en el sentido de la hora pico (mañana) | B11: Entrada → tren, media (s) | C11: =F31 -> 167.36 | D11: =F32 -> 0.4812022 | E11: =F33 -> 10 | F11: =F67 -> 167.87 | G11: =F68 -> 0.48773855 | H11: =F69 -> 10 | I11: =F11-C11 -> 0.51 | J11: =(D11^2/E11+G11^2/H11)^2/((D11^2/E11)^2/(E11-1)+(G11^2/H11)^2/(H11-1)) -> 17.996724 | K11: =_xlfn.T.INV.2T(0.05,J11) -> 2.1098156 | L11: =K11*SQRT(D11^2/E11+G11^2/H11) -> 0.45712671 | M11: =I11-L11 -> 0.052873291 | N11: =I11+L11 -> 0.96712671 | O11: =100*I11/C11 -> 0.30473231
A12: Mecánicas del lado Roca en el sentido de la hora pico (mañana) | B12: Tren → salida, media (s) | C12: =K31 -> 162.59 | D12: =K32 -> 1.2661841 | E12: =K33 -> 10 | F12: =K67 -> 154.68 | G12: =K68 -> 1.397458 | H12: =K69 -> 10 | I12: =F12-C12 -> -7.91 | J12: =(D12^2/E12+G12^2/H12)^2/((D12^2/E12)^2/(E12-1)+(G12^2/H12)^2/(H12-1)) -> 17.827634 | K12: =_xlfn.T.INV.2T(0.05,J12) -> 2.1098156 | L12: =K12*SQRT(D12^2/E12+G12^2/H12) -> 1.2581492 | M12: =I12-L12 -> -9.1681492 | N12: =I12+L12 -> -6.6518508 | O12: =100*I12/C12 -> -4.8649978
A13: Mecánicas del lado Roca en el sentido de la hora pico (tarde) | B13: Entrada → tren, media (s) | C13: =F85 -> 158.67 | D13: =F86 -> 0.56969778 | E13: =F87 -> 10 | F13: =F114 -> 156.96667 | G13: =F115 -> 0.4163332 | H13: =F116 -> 3 | I13: =F13-C13 -> -1.7033333 | J13: =(D13^2/E13+G13^2/H13)^2/((D13^2/E13)^2/(E13-1)+(G13^2/H13)^2/(H13-1)) -> 4.5583715 | K13: =_xlfn.T.INV.2T(0.05,J13) -> 2.7764451 | L13: =K13*SQRT(D13^2/E13+G13^2/H13) -> 0.83401256 | M13: =I13-L13 -> -2.5373459 | N13: =I13+L13 -> -0.86932077 | O13: =100*I13/C13 -> -1.0735069
A14: Mecánicas del lado Roca en el sentido de la hora pico (tarde) | B14: Tren → salida, media (s) | C14: =K85 -> 163.69 | D14: =K86 -> 0.4794673 | E14: =K87 -> 10 | F14: =K114 -> 161.36667 | G14: =K115 -> 0.47258156 | H14: =K116 -> 3 | I14: =F14-C14 -> -2.3233333 | J14: =(D14^2/E14+G14^2/H14)^2/((D14^2/E14)^2/(E14-1)+(G14^2/H14)^2/(H14-1)) -> 3.3548522 | K14: =_xlfn.T.INV.2T(0.05,J14) -> 3.1824463 | L14: =K14*SQRT(D14^2/E14+G14^2/H14) -> 0.99337875 | M14: =I14-L14 -> -3.3167121 | N14: =I14+L14 -> -1.3299546 | O14: =100*I14/C14 -> -1.4193496
A15: Salida elegida al azar (tarde) | B15: Entrada → tren, media (s) | C15: =F85 -> 158.67 | D15: =F86 -> 0.56969778 | E15: =F87 -> 10 | F15: =F132 -> 158.44 | G15: =F133 -> 0.70898989 | H15: =F134 -> 10 | I15: =F15-C15 -> -0.23 | J15: =(D15^2/E15+G15^2/H15)^2/((D15^2/E15)^2/(E15-1)+(G15^2/H15)^2/(H15-1)) -> 17.202503 | K15: =_xlfn.T.INV.2T(0.05,J15) -> 2.1098156 | L15: =K15*SQRT(D15^2/E15+G15^2/H15) -> 0.606814 | M15: =I15-L15 -> -0.836814 | N15: =I15+L15 -> 0.376814 | O15: =100*I15/C15 -> -0.14495494
A16: Salida elegida al azar (tarde) | B16: Tren → salida, media (s) | C16: =K85 -> 163.69 | D16: =K86 -> 0.4794673 | E16: =K87 -> 10 | F16: =K132 -> 180.14 | G16: =K133 -> 0.39496835 | H16: =K134 -> 10 | I16: =F16-C16 -> 16.45 | J16: =(D16^2/E16+G16^2/H16)^2/((D16^2/E16)^2/(E16-1)+(G16^2/H16)^2/(H16-1)) -> 17.363397 | K16: =_xlfn.T.INV.2T(0.05,J16) -> 2.1098156 | L16: =K16*SQRT(D16^2/E16+G16^2/H16) -> 0.41445333 | M16: =I16-L16 -> 16.035547 | N16: =I16+L16 -> 16.864453 | O16: =100*I16/C16 -> 10.049484
A17: INV.T.2C toma la parte entera de los grados de libertad de Welch.
A19: Mañana (8 a 9 h), caso base: 70 % de los pasajeros va o viene del Roca (n = 10)
A20: Réplica | B20: Tiempo simulado (s) | C20: Entraron a la estación | D20: Subieron al tren | E20: Quedaron adentro al final de la hora | F20: Entrada → tren: media (s) | G20: Entrada → tren: mediana (s) | H20: Entrada → tren: percentil 90 (s) | I20: Entrada → tren: percentil 95 (s) | J20: Bajaron del tren y salieron | K20: Tren → salida: media (s) | L20: Tren → salida: mediana (s) | M20: Tren → salida: percentil 90 (s) | N20: Tren → salida: percentil 95 (s) | O20: Máximo de personas esperando a la vez en el andén norte | P20: Escalera más cargada: mecánica ESM-09 (baja), pas./h
A21: 1 | B21: 3600 | C21: 7325 | D21: 7099 | E21: 226 | F21: 166.4 | G21: 165.5 | H21: 215.2 | I21: 227.8 | J21: 753 | K21: 162.7 | L21: 161.4 | M21: 212.6 | N21: 220.7 | O21: 343 | P21: 4675
A22: 2 | B22: 3600 | C22: 7483 | D22: 7223 | E22: 260 | F22: 167.8 | G22: 168.2 | H22: 215.6 | I22: 228.3 | J22: 746 | K22: 161.6 | L22: 158.9 | M22: 215 | N22: 226.2 | O22: 338 | P22: 4724
A23: 3 | B23: 3600 | C23: 7384 | D23: 7119 | E23: 265 | F23: 166.8 | G23: 166.8 | H23: 215.2 | I23: 228.2 | J23: 756 | K23: 163.4 | L23: 163 | M23: 213.2 | N23: 222 | O23: 334 | P23: 4758
A24: 4 | B24: 3600 | C24: 7471 | D24: 7241 | E24: 230 | F24: 167.7 | G24: 167.1 | H24: 215.9 | I24: 229.6 | J24: 801 | K24: 163.6 | L24: 162.6 | M24: 213.1 | N24: 224.2 | O24: 334 | P24: 4711
A25: 5 | B25: 3600 | C25: 7319 | D25: 7070 | E25: 249 | F25: 167.9 | G25: 167.2 | H25: 216.9 | I25: 228.5 | J25: 762 | K25: 163.2 | L25: 162.4 | M25: 216.6 | N25: 227.2 | O25: 328 | P25: 4713
A26: 6 | B26: 3600 | C26: 7444 | D26: 7181 | E26: 263 | F26: 167.4 | G26: 166.9 | H26: 216.3 | I26: 228.5 | J26: 696 | K26: 161.2 | L26: 159.2 | M26: 213.7 | N26: 222.4 | O26: 321 | P26: 4785
A27: 7 | B27: 3600 | C27: 7557 | D27: 7295 | E27: 262 | F27: 167.8 | G27: 167.6 | H27: 217.1 | I27: 229.1 | J27: 759 | K27: 160.1 | L27: 157.2 | M27: 211.7 | N27: 224.1 | O27: 330 | P27: 4823
A28: 8 | B28: 3600 | C28: 7282 | D28: 7060 | E28: 222 | F28: 167.4 | G28: 167 | H28: 216.8 | I28: 228.4 | J28: 716 | K28: 163.4 | L28: 162.4 | M28: 213.3 | N28: 221.6 | O28: 320 | P28: 4692
A29: 9 | B29: 3600 | C29: 7282 | D29: 7039 | E29: 243 | F29: 167.2 | G29: 167 | H29: 216.4 | I29: 228.5 | J29: 776 | K29: 164.2 | L29: 162.8 | M29: 215.1 | N29: 224.4 | O29: 319 | P29: 4646
A30: 10 | B30: 3600 | C30: 7276 | D30: 7056 | E30: 220 | F30: 167.2 | G30: 167.3 | H30: 216.6 | I30: 228.9 | J30: 790 | K30: 162.5 | L30: 161.7 | M30: 214 | N30: 226.7 | O30: 317 | P30: 4660
A31: Media | C31: =AVERAGE(C21:C30) -> 7382.3 | D31: =AVERAGE(D21:D30) -> 7138.3 | E31: =AVERAGE(E21:E30) -> 244 | F31: =AVERAGE(F21:F30) -> 167.36 | G31: =AVERAGE(G21:G30) -> 167.06 | H31: =AVERAGE(H21:H30) -> 216.2 | I31: =AVERAGE(I21:I30) -> 228.58 | J31: =AVERAGE(J21:J30) -> 755.5 | ... P31: =AVERAGE(P21:P30) -> 4718.7
A32: Desvío | C32: =_xlfn.STDEV.S(C21:C30) -> 100.58059 | D32: =_xlfn.STDEV.S(D21:D30) -> 90.33647 | E32: =_xlfn.STDEV.S(E21:E30) -> 18.220867 | F32: =_xlfn.STDEV.S(F21:F30) -> 0.4812022 | G32: =_xlfn.STDEV.S(G21:G30) -> 0.68345527 | H32: =_xlfn.STDEV.S(H21:H30) -> 0.69282032 | I32: =_xlfn.STDEV.S(I21:I30) -> 0.50508525 | J32: =_xlfn.STDEV.S(J21:J30) -> 31.503968 | ... P32: =_xlfn.STDEV.S(P21:P30) -> 56.067519
A33: n (réplicas) | C33: =COUNT(C21:C30) -> 10 | D33: =COUNT(D21:D30) -> 10 | E33: =COUNT(E21:E30) -> 10 | F33: =COUNT(F21:F30) -> 10 | G33: =COUNT(G21:G30) -> 10 | H33: =COUNT(H21:H30) -> 10 | I33: =COUNT(I21:I30) -> 10 | J33: =COUNT(J21:J30) -> 10 | ... P33: =COUNT(P21:P30) -> 10
A34: t de Student (95 %) | C34: =_xlfn.T.INV.2T(0.05,C33-1) -> 2.2621572 | D34: =_xlfn.T.INV.2T(0.05,D33-1) -> 2.2621572 | E34: =_xlfn.T.INV.2T(0.05,E33-1) -> 2.2621572 | F34: =_xlfn.T.INV.2T(0.05,F33-1) -> 2.2621572 | G34: =_xlfn.T.INV.2T(0.05,G33-1) -> 2.2621572 | H34: =_xlfn.T.INV.2T(0.05,H33-1) -> 2.2621572 | I34: =_xlfn.T.INV.2T(0.05,I33-1) -> 2.2621572 | J34: =_xlfn.T.INV.2T(0.05,J33-1) -> 2.2621572 | ... P34: =_xlfn.T.INV.2T(0.05,P33-1) -> 2.2621572
A35: IC 95 % (±) | C35: =C34*C32/SQRT(C33) -> 71.951021 | D35: =D34*D32/SQRT(D33) -> 64.622818 | E35: =E34*E32/SQRT(E33) -> 13.034423 | F35: =F34*F32/SQRT(F33) -> 0.34423132 | G35: =G34*G32/SQRT(G33) -> 0.48891445 | H35: =H34*H32/SQRT(H33) -> 0.4956138 | I35: =I34*I32/SQRT(I33) -> 0.36131622 | J35: =J34*J32/SQRT(J33) -> 22.536581 | ... P35: =P34*P32/SQRT(P33) -> 40.108287
A37: Mañana, si solo el 30 % fuera del Roca (n = 10)
A38: Réplica | B38: Tiempo simulado (s) | C38: Entraron a la estación | D38: Subieron al tren | E38: Quedaron adentro al final de la hora | F38: Entrada → tren: media (s) | G38: Entrada → tren: mediana (s) | H38: Entrada → tren: percentil 90 (s) | I38: Entrada → tren: percentil 95 (s) | J38: Bajaron del tren y salieron | K38: Tren → salida: media (s) | L38: Tren → salida: mediana (s) | M38: Tren → salida: percentil 90 (s) | N38: Tren → salida: percentil 95 (s) | O38: Máximo de personas esperando a la vez en el andén norte | P38: Escalera más cargada: mecánica ESM-09 (baja), pas./h
A39: 1 | B39: 3600 | C39: 7248 | D39: 7047 | E39: 201 | F39: 163.6 | G39: 163.1 | H39: 212 | I39: 225.2 | J39: 731 | K39: 158.4 | L39: 154 | M39: 207.8 | N39: 219.2 | O39: 333 | P39: 4716
A40: 2 | B40: 3600 | C40: 7357 | D40: 7123 | E40: 234 | F40: 164.5 | G40: 164.3 | H40: 213.6 | I40: 224.3 | J40: 742 | K40: 157.8 | L40: 153.6 | M40: 208.8 | N40: 218.8 | O40: 330 | P40: 4777
A41: 3 | B41: 3600 | C41: 7483 | D41: 7241 | E41: 242 | F41: 163.9 | G41: 163.4 | H41: 212.3 | I41: 225 | J41: 711 | K41: 157.1 | L41: 154.5 | M41: 210.2 | N41: 220 | O41: 362 | P41: 4814
A42: 4 | B42: 3600 | C42: 7400 | D42: 7169 | E42: 231 | F42: 163.8 | G42: 163.1 | H42: 212.9 | I42: 225.9 | J42: 754 | K42: 158.5 | L42: 157.3 | M42: 207.4 | N42: 216.8 | O42: 337 | P42: 4936
A43: 5 | B43: 3600 | C43: 7400 | D43: 7169 | E43: 231 | F43: 163.8 | G43: 163.6 | H43: 212.9 | I43: 224.2 | J43: 754 | K43: 159 | L43: 156.2 | M43: 207.5 | N43: 219.9 | O43: 327 | P43: 4812
...

Sheet Control base
A1: Réplica | B1: Semilla | C1: Pasajeros que entraron | D1: Pasajeros que llegaron a destino | E1: Viaje medio (s) | F1: Espera media (s) | G1: Ascensos por viaje (trenes que toma cada pasajero) | H1: Pasajeros que no subieron al primer tren (día) | I1: Pasajeros en la red a la vez (máx.) | J1: Trenes en servicio (máx.) | K1: Retenciones de trenes por separación | L1: Detención media en estación (s) | M1: Pasajeros que abandonaron
A2: 1 | B2: 1 | C2: 828602 | D2: 828169 | E2: 1108.8 | F2: 186.9 | G2: 1.4421 | H2: 2340 | I2: 26745 | J2: 80 | K2: 45 | L2: 24 | M2: 0
A3: 2 | B3: 2 | C3: 828366 | D3: 827916 | E3: 1110.3 | F3: 188.1 | G3: 1.4419 | H3: 3439 | I3: 27086 | J3: 82 | K3: 42 | L3: 24 | M3: 0
A4: 3 | B4: 3 | C4: 827159 | D4: 826721 | E4: 1109.9 | F4: 187.6 | G4: 1.4429 | H4: 2338 | I4: 26817 | J4: 82 | K4: 25 | L4: 24 | M4: 0
A5: 4 | B5: 4 | C5: 827535 | D5: 827169 | E5: 1107.2 | F5: 184.9 | G5: 1.4431 | H5: 2591 | I5: 26886 | J5: 81 | K5: 35 | L5: 24 | M5: 0
A6: 5 | B6: 5 | C6: 827349 | D6: 826902 | E6: 1111 | F6: 188.8 | G6: 1.4428 | H6: 3226 | I6: 26771 | J6: 83 | K6: 31 | L6: 24 | M6: 0
A7: 6 | B7: 6 | C7: 827087 | D7: 826639 | E7: 1110.5 | F7: 187.2 | G7: 1.4431 | H7: 5194 | I7: 26523 | J7: 82 | K7: 35 | L7: 24 | M7: 0
A8: 7 | B8: 7 | C8: 828212 | D8: 827795 | E8: 1110.2 | F8: 188.2 | G8: 1.4424 | H8: 3352 | I8: 27152 | J8: 83 | K8: 28 | L8: 24 | M8: 0
A9: 8 | B9: 8 | C9: 827037 | D9: 826659 | E9: 1110.7 | F9: 189.1 | G9: 1.4427 | H9: 3454 | I9: 26494 | J9: 83 | K9: 39 | L9: 24 | M9: 0
A10: 9 | B10: 9 | C10: 828365 | D10: 827987 | E10: 1110.6 | F10: 188.4 | G10: 1.4441 | H10: 1259 | I10: 26993 | J10: 81 | K10: 35 | L10: 24 | M10: 0
A11: 10 | B11: 10 | C11: 827293 | D11: 826908 | E11: 1111 | F11: 189.1 | G11: 1.4426 | H11: 3629 | I11: 27240 | J11: 81 | K11: 48 | L11: 24 | M11: 0
A12: 11 | B12: 11 | C12: 827031 | D12: 826595 | E12: 1110.4 | F12: 188.8 | G12: 1.4425 | H12: 2310 | I12: 26825 | J12: 82 | K12: 46 | L12: 24 | M12: 0
A13: 12 | B13: 12 | C13: 827821 | D13: 827407 | E13: 1110 | F13: 187.8 | G13: 1.4429 | H13: 3873 | I13: 26551 | J13: 80 | K13: 52 | L13: 24 | M13: 0
... A101: 100 | B101: 100 | C101: 827417 | D101: 826955 | E101: 1110 | F101: 187.7 | G101: 1.4431 | H101: 1432 | I101: 26818 | J101: 82 | K101: 35 | L101: 24 | M101: 0

Sheet Control F90
A1: Réplica | B1: Semilla | C1: Pasajeros que entraron | D1: Pasajeros que llegaron a destino | E1: Viaje medio (s) | F1: Espera media (s) | G1: Ascensos por viaje (trenes que toma cada pasajero) | H1: Pasajeros que no subieron al primer tren (día) | I1: Pasajeros en la red a la vez (máx.) | J1: Trenes en servicio (máx.) | K1: Retenciones de trenes por separación | L1: Detención media en estación (s) | M1: Pasajeros que abandonaron
A2: 1 | B2: 1 | C2: 912926 | D2: 912300 | E2: 1065.6 | F2: 176 | G2: 1.4658 | H2: 4524 | I2: 28302 | J2: 106 | K2: 51 | L2: 25.59 | M2: 0
A3: 2 | B3: 2 | C3: 911108 | D3: 910493 | E3: 1063.2 | F3: 173.8 | G3: 1.4656 | H3: 1774 | I3: 27972 | J3: 105 | K3: 34 | L3: 25.59 | M3: 0
A4: 3 | B4: 3 | C4: 911249 | D4: 910715 | E4: 1070.1 | F4: 180.1 | G4: 1.4663 | H4: 11710 | I4: 28253 | J4: 106 | K4: 33 | L4: 25.6 | M4: 0
A5: 4 | B5: 4 | C5: 911876 | D5: 911273 | E5: 1064.7 | F5: 175.5 | G5: 1.4657 | H5: 4227 | I5: 28177 | J5: 105 | K5: 43 | L5: 25.59 | M5: 0
A6: 5 | B6: 5 | C6: 911644 | D6: 911088 | E6: 1062.8 | F6: 174.4 | G6: 1.4654 | H6: 5972 | I6: 28119 | J6: 107 | K6: 21 | L6: 25.58 | M6: 0
A7: 6 | B7: 6 | C7: 910636 | D7: 909965 | E7: 1063.4 | F7: 174.7 | G7: 1.4647 | H7: 3717 | I7: 28141 | J7: 108 | K7: 32 | L7: 25.58 | M7: 0
A8: 7 | B8: 7 | C8: 911156 | D8: 910561 | E8: 1065.7 | F8: 176.9 | G8: 1.4647 | H8: 4575 | I8: 28293 | J8: 105 | K8: 29 | L8: 25.59 | M8: 0
A9: 8 | B9: 8 | C9: 909704 | D9: 909142 | E9: 1066.5 | F9: 177.2 | G9: 1.466 | H9: 4065 | I9: 27982 | J9: 105 | K9: 42 | L9: 25.58 | M9: 0
A10: 9 | B10: 9 | C10: 911380 | D10: 910826 | E10: 1062.5 | F10: 173.7 | G10: 1.4662 | H10: 6400 | I10: 28307 | J10: 105 | K10: 43 | L10: 25.58 | M10: 0
A11: 10 | B11: 10 | C11: 911280 | D11: 910690 | E11: 1064.1 | F11: 174.2 | G11: 1.4659 | H11: 1556 | I11: 27799 | J11: 106 | K11: 24 | L11: 25.58 | M11: 0
A12: 11 | B12: 11 | C12: 910032 | D12: 909435 | E12: 1064.8 | F12: 174.6 | G12: 1.4671 | H12: 3298 | I12: 28758 | J12: 106 | K12: 31 | L12: 25.58 | M12: 0
A13: 12 | B13: 12 | C13: 910990 | D13: 910426 | E13: 1065.4 | F13: 176.4 | G13: 1.4648 | H13: 5468 | I13: 28195 | J13: 108 | K13: 41 | L13: 25.59 | M13: 0
... A101: 100 | B101: 100 | C101: 911048 | D101: 910503 | E101: 1066.8 | F101: 177.9 | G101: 1.4657 | H101: 4124 | I101: 28260 | J101: 108 | K101: 39 | L101: 25.6 | M101: 0

Sheet Control F100
A1: Réplica | B1: Semilla | C1: Pasajeros que entraron | D1: Pasajeros que llegaron a destino | E1: Viaje medio (s) | F1: Espera media (s) | G1: Ascensos por viaje (trenes que toma cada pasajero) | H1: Pasajeros que no subieron al primer tren (día) | I1: Pasajeros en la red a la vez (máx.) | J1: Trenes en servicio (máx.) | K1: Retenciones de trenes por separación | L1: Detención media en estación (s) | M1: Pasajeros que abandonaron
A2: 1 | B2: 1 | C2: 911920 | D2: 911359 | E2: 1068.1 | F2: 178.5 | G2: 1.4663 | H2: 6999 | I2: 28661 | J2: 103 | K2: 40 | L2: 25.47 | M2: 0
A3: 2 | B3: 2 | C3: 911853 | D3: 911295 | E3: 1065.4 | F3: 175.9 | G3: 1.4661 | H3: 3486 | I3: 28413 | J3: 102 | K3: 37 | L3: 25.46 | M3: 0
A4: 3 | B4: 3 | C4: 909820 | D4: 909213 | E4: 1064.6 | F4: 175.5 | G4: 1.4657 | H4: 5048 | I4: 28706 | J4: 104 | K4: 56 | L4: 25.46 | M4: 0
A5: 4 | B5: 4 | C5: 910079 | D5: 909430 | E5: 1064.1 | F5: 174.6 | G5: 1.4654 | H5: 1552 | I5: 28160 | J5: 102 | K5: 35 | L5: 25.46 | M5: 0
A6: 5 | B6: 5 | C6: 911475 | D6: 910855 | E6: 1066 | F6: 177.5 | G6: 1.4658 | H6: 6845 | I6: 28379 | J6: 102 | K6: 35 | L6: 25.47 | M6: 0
A7: 6 | B7: 6 | C7: 911133 | D7: 910512 | E7: 1069.3 | F7: 180.6 | G7: 1.4651 | H7: 9538 | I7: 28752 | J7: 101 | K7: 42 | L7: 25.47 | M7: 0
A8: 7 | B8: 7 | C8: 911585 | D8: 910977 | E8: 1067.2 | F8: 177.6 | G8: 1.4656 | H8: 3937 | I8: 29025 | J8: 102 | K8: 40 | L8: 25.46 | M8: 0
A9: 8 | B9: 8 | C9: 910743 | D9: 910149 | E9: 1062.5 | F9: 174.5 | G9: 1.4655 | H9: 4091 | I9: 28127 | J9: 102 | K9: 40 | L9: 25.46 | M9: 0
A10: 9 | B10: 9 | C10: 909688 | D10: 909080 | E10: 1064.4 | F10: 175.7 | G10: 1.466 | H10: 1879 | I10: 27995 | J10: 103 | K10: 33 | L10: 25.47 | M10: 0
A11: 10 | B11: 10 | C11: 912042 | D11: 911480 | E11: 1064.9 | F11: 176.1 | G11: 1.465 | H11: 1663 | I11: 28332 | J11: 103 | K11: 41 | L11: 25.47 | M11: 0
A12: 11 | B12: 11 | C12: 910968 | D12: 910420 | E12: 1068.3 | F12: 180 | G12: 1.4655 | H12: 6017 | I12: 28946 | J12: 103 | K12: 30 | L12: 25.48 | M12: 0
A13: 12 | B13: 12 | C13: 911499 | D13: 910943 | E13: 1067.1 | F13: 177.4 | G13: 1.4661 | H13: 4470 | I13: 28565 | J13: 104 | K13: 52 | L13: 25.46 | M13: 0
... A101: 100 | B101: 100 | C101: 910304 | D101: 909751 | E101: 1066.1 | F101: 178.1 | G101: 1.465 | H101: 2197 | I101: 28489 | J101: 103 | K101: 36 | L101: 25.47 | M101: 0

Sheet Control F120
A1: Réplica | B1: Semilla | C1: Pasajeros que entraron | D1: Pasajeros que llegaron a destino | E1: Viaje medio (s) | F1: Espera media (s) | G1: Ascensos por viaje (trenes que toma cada pasajero) | H1: Pasajeros que no subieron al primer tren (día) | I1: Pasajeros en la red a la vez (máx.) | J1: Trenes en servicio (máx.) | K1: Retenciones de trenes por separación | L1: Detención media en estación (s) | M1: Pasajeros que abandonaron
A2: 1 | B2: 1 | C2: 911816 | D2: 911271 | E2: 1064.8 | F2: 175.5 | G2: 1.4653 | H2: 3924 | I2: 28548 | J2: 100 | K2: 68 | L2: 25.26 | M2: 0
A3: 2 | B3: 2 | C3: 910888 | D3: 910318 | E3: 1066.6 | F3: 176.9 | G3: 1.467 | H3: 1202 | I3: 28090 | J3: 100 | K3: 41 | L3: 25.27 | M3: 0
A4: 3 | B4: 3 | C4: 910498 | D4: 909900 | E4: 1067.6 | F4: 178.5 | G4: 1.4655 | H4: 3022 | I4: 28283 | J4: 100 | K4: 25 | L4: 25.28 | M4: 0
A5: 4 | B5: 4 | C5: 911818 | D5: 911233 | E5: 1069.5 | F5: 180.1 | G5: 1.4661 | H5: 1890 | I5: 28149 | J5: 100 | K5: 40 | L5: 25.28 | M5: 0
A6: 5 | B6: 5 | C6: 910708 | D6: 910132 | E6: 1065.8 | F6: 177.9 | G6: 1.4651 | H6: 2815 | I6: 28125 | J6: 99 | K6: 39 | L6: 25.27 | M6: 0
A7: 6 | B7: 6 | C7: 909496 | D7: 908856 | E7: 1068.9 | F7: 179.6 | G7: 1.4652 | H7: 4268 | I7: 27918 | J7: 103 | K7: 59 | L7: 25.28 | M7: 0
A8: 7 | B8: 7 | C8: 911596 | D8: 910964 | E8: 1068.1 | F8: 179.5 | G8: 1.4648 | H8: 6236 | I8: 28296 | J8: 99 | K8: 31 | L8: 25.27 | M8: 0
A9: 8 | B9: 8 | C9: 910899 | D9: 910253 | E9: 1067.2 | F9: 179.1 | G9: 1.4661 | H9: 3985 | I9: 28222 | J9: 99 | K9: 43 | L9: 25.27 | M9: 0
A10: 9 | B10: 9 | C10: 910225 | D10: 909636 | E10: 1065.1 | F10: 177.2 | G10: 1.466 | H10: 2180 | I10: 27947 | J10: 101 | K10: 32 | L10: 25.27 | M10: 0
A11: 10 | B11: 10 | C11: 911599 | D11: 911044 | E11: 1067.8 | F11: 178 | G11: 1.4659 | H11: 3024 | I11: 27768 | J11: 99 | K11: 34 | L11: 25.28 | M11: 0
A12: 11 | B12: 11 | C12: 909831 | D12: 909245 | E12: 1069.5 | F12: 180.8 | G12: 1.4657 | H12: 3714 | I12: 28184 | J12: 101 | K12: 34 | L12: 25.28 | M12: 0
A13: 12 | B13: 12 | C13: 911477 | D13: 910948 | E13: 1067.6 | F13: 178.4 | G13: 1.4656 | H13: 3224 | I13: 28700 | J13: 100 | K13: 25 | L13: 25.27 | M13: 0
... A101: 100 | B101: 100 | C101: 910059 | D101: 909498 | E101: 1064 | F101: 174.7 | G101: 1.4659 | H101: 3096 | I101: 28314 | J101: 101 | K101: 29 | L101: 25.26 | M101: 0

Sheet Control F150
A1: Réplica | B1: Semilla | C1: Pasajeros que entraron | D1: Pasajeros que llegaron a destino | E1: Viaje medio (s) | F1: Espera media (s) | G1: Ascensos por viaje (trenes que toma cada pasajero) | H1: Pasajeros que no subieron al primer tren (día) | I1: Pasajeros en la red a la vez (máx.) | J1: Trenes en servicio (máx.) | K1: Retenciones de trenes por separación | L1: Detención media en estación (s) | M1: Pasajeros que abandonaron
A2: 1 | B2: 1 | C2: 911023 | D2: 910454 | E2: 1066.4 | F2: 177.7 | G2: 1.4628 | H2: 2779 | I2: 28087 | J2: 98 | K2: 35 | L2: 25.06 | M2: 0
A3: 2 | B3: 2 | C3: 912914 | D3: 912314 | E3: 1072.5 | F3: 183.2 | G3: 1.4633 | H3: 3957 | I3: 28527 | J3: 97 | K3: 46 | L3: 25.07 | M3: 0
A4: 3 | B4: 3 | C4: 910605 | D4: 910037 | E4: 1069.5 | F4: 180.9 | G4: 1.4634 | H4: 2637 | I4: 27891 | J4: 96 | K4: 39 | L4: 25.07 | M4: 0
A5: 4 | B5: 4 | C5: 911933 | D5: 911191 | E5: 1071.7 | F5: 181.6 | G5: 1.4636 | H5: 7475 | I5: 28893 | J5: 97 | K5: 50 | L5: 25.06 | M5: 0
A6: 5 | B6: 5 | C6: 909962 | D6: 909384 | E6: 1073.3 | F6: 184.6 | G6: 1.4634 | H6: 6324 | I6: 28263 | J6: 97 | K6: 49 | L6: 25.06 | M6: 0
A7: 6 | B7: 6 | C7: 909908 | D7: 909286 | E7: 1069.5 | F7: 180.5 | G7: 1.4632 | H7: 3111 | I7: 28223 | J7: 99 | K7: 31 | L7: 25.06 | M7: 0
A8: 7 | B8: 7 | C8: 912654 | D8: 912077 | E8: 1072.6 | F8: 183.5 | G8: 1.4637 | H8: 2954 | I8: 28401 | J8: 95 | K8: 43 | L8: 25.07 | M8: 0
A9: 8 | B9: 8 | C9: 911427 | D9: 910812 | E9: 1071.4 | F9: 182.6 | G9: 1.4641 | H9: 8407 | I9: 28215 | J9: 98 | K9: 46 | L9: 25.06 | M9: 0
A10: 9 | B10: 9 | C10: 910496 | D10: 909895 | E10: 1070 | F10: 181.4 | G10: 1.4642 | H10: 3554 | I10: 28210 | J10: 97 | K10: 42 | L10: 25.06 | M10: 0
A11: 10 | B11: 10 | C11: 911179 | D11: 910573 | E11: 1068.3 | F11: 180.2 | G11: 1.4634 | H11: 1298 | I11: 28287 | J11: 96 | K11: 30 | L11: 25.07 | M11: 0
A12: 11 | B12: 11 | C12: 910633 | D12: 909984 | E12: 1069.2 | F12: 180 | G12: 1.4639 | H12: 7030 | I12: 28247 | J12: 98 | K12: 60 | L12: 25.06 | M12: 0
A13: 12 | B13: 12 | C13: 911263 | D13: 910720 | E13: 1069.8 | F13: 180.4 | G13: 1.4641 | H13: 6253 | I13: 28469 | J13: 96 | K13: 55 | L13: 25.06 | M13: 0
... A101: 100 | B101: 100 | C101: 910528 | D101: 909961 | E101: 1067.6 | F101: 178.8 | G101: 1.4635 | H101: 2755 | I101: 27916 | J101: 97 | K101: 30 | L101: 25.06 | M101: 0

Sheet Control F189
A1: Réplica | B1: Semilla | C1: Pasajeros que entraron | D1: Pasajeros que llegaron a destino | E1: Viaje medio (s) | F1: Espera media (s) | G1: Ascensos por viaje (trenes que toma cada pasajero) | H1: Pasajeros que no subieron al primer tren (día) | I1: Pasajeros en la red a la vez (máx.) | J1: Trenes en servicio (máx.) | K1: Retenciones de trenes por separación | L1: Detención media en estación (s) | M1: Pasajeros que abandonaron
A2: 1 | B2: 1 | C2: 912025 | D2: 911386 | E2: 1076.7 | F2: 187.3 | G2: 1.4647 | H2: 4855 | I2: 28683 | J2: 91 | K2: 52 | L2: 24.88 | M2: 0
A3: 2 | B3: 2 | C3: 911478 | D3: 910903 | E3: 1071.5 | F3: 182 | G3: 1.4633 | H3: 1518 | I3: 28138 | J3: 94 | K3: 43 | L3: 24.87 | M3: 0
A4: 3 | B4: 3 | C4: 909069 | D4: 908470 | E4: 1073 | F4: 184.5 | G4: 1.4632 | H4: 1327 | I4: 28336 | J4: 95 | K4: 29 | L4: 24.88 | M4: 0
A5: 4 | B5: 4 | C5: 909735 | D5: 909168 | E5: 1072.9 | F5: 183.4 | G5: 1.4631 | H5: 2836 | I5: 28155 | J5: 93 | K5: 33 | L5: 24.87 | M5: 0
A6: 5 | B6: 5 | C6: 911254 | D6: 910658 | E6: 1074.3 | F6: 186.2 | G6: 1.462 | H6: 1524 | I6: 28569 | J6: 91 | K6: 41 | L6: 24.88 | M6: 0
A7: 6 | B7: 6 | C7: 909943 | D7: 909323 | E7: 1078.2 | F7: 189 | G7: 1.4627 | H7: 8591 | I7: 28587 | J7: 94 | K7: 60 | L7: 24.88 | M7: 0
A8: 7 | B8: 7 | C8: 911816 | D8: 911181 | E8: 1076.4 | F8: 187.3 | G8: 1.4627 | H8: 5341 | I8: 28869 | J8: 92 | K8: 26 | L8: 24.88 | M8: 0
A9: 8 | B9: 8 | C9: 910364 | D9: 909803 | E9: 1073.1 | F9: 183.9 | G9: 1.4635 | H9: 4654 | I9: 28211 | J9: 93 | K9: 44 | L9: 24.87 | M9: 0
A10: 9 | B10: 9 | C10: 910176 | D10: 909553 | E10: 1074.5 | F10: 185.6 | G10: 1.4637 | H10: 2094 | I10: 28530 | J10: 94 | K10: 33 | L10: 24.88 | M10: 0
